Workbook

Sheet Forside
A9: NFSP0598
A10: Høje Taastrup – Roskilde St. Fri strækning
A24: Tilbudsliste (TBL)
A43: Dato: | B43: 45980.575
A44: Rev: | B44: 5.0
A45: Udarbejdet af: | B45: [Åbent tekstfelt]
A46: Godkendt: | B46: [Åbent tekstfelt]

Sheet Revisionslog
A5: Revisionslog
A8: Revision | B8: Int. | C8: Dato | D8: Beskrivelse af ændring
A9: 1.0 | C9: 45771.325 | D9: Første version
A10: 2.0 | C10: 45932.295 | D10: Se farvemarkeringer i bilag Høje Taastrup – Roskilde St. Fri strækning_NFSP0598_v2.xlsx
A11: 3.0 | C11: 45952.447 | D11: Se farvemarkeringer i bilag Høje Taastrup – Roskilde St. Fri strækning_NFSP0598_v3.xlsx
A12: 4.0 | C12: 45967.575 | D12: Se farvemarkeringer i bilag Høje Taastrup – Roskilde St. Fri strækning_NFSP0598_v4.xlsx
A13: 5.0 | C13: 45980.575 | D13: Se farvemarkeringer i bilag Høje Taastrup – Roskilde St. Fri strækning_NFSP0598_v5.xlsx

Sheet Hovedtilbudsliste
A1: Tilbudsliste
A3: Undertegnede entreprenør tilbyder herved Banedanmark at udføre ydelser i henhold til udbudsmaterialet vedr.
A4: NFSP0598 Høje Taastrup – Roskilde St. Fri strækning
A5: [Åbent tekstfelt]
A6: Hovedtilbudsliste
A7: FP | B7: Arbejdets art | D7: I alt DKK
A8: 3 | B8: Spor | D8: ='3 Spor'!T18 -> 13156356
A9: 4 | B9: Jord og ballast | D9: ='4 Jord og ballast'!T16 -> 5385023
A10: 5 | B10: Afvanding | D10: ='5 Afvanding'!T81 -> 35853511
A11: 6 | B11: Kabelomlægning og føringsveje | D11: ='6 Kabelomlægning og føringsveje'!T22 -> 5951162
A12: 8 | B12: Perroner | D12: ='8 Perroner'!T14 -> 1424178
A13: 9 | B13: Kørestrøm | D13: ='9 Kørestrøm'!T58 -> 11396006
A14: 10 | B14: Sikring | D14: ='10 Sikring'!T33 -> 6696915
A15: 12 | B15: Broer og konstruktioner | D15: ='12 Broer og konstruktioner'!T26 -> 2369231
A16: 14 | B16: Håndtering og bortskaffelse | D16: ='14 Håndtering og bortskaffelse'!T19 -> 9974303
A17: 15 | B17: Administration og arbejdsplads | D17: ='15 Administration og arbejdspla'!T43 -> 48827255
A18: 16 | B18: Ændringsydelser | D18: ='16 Ændringsydelser'!T50 -> 8877758
B26: Samlet tilbudssum | D26: =SUM(D8:D25) -> 149911698
A28: Samlet tilbudssum skrevet: | C28: en-fire-ni-ni-fire-syv-fem-seks-seks/00
A30: Alle ovennævnte beløb vil blive tillagt moms efter gældende lov.
A31: Tilbuddet er afgivet i henhold til det i rettelsesblad(e) til de bydende nr.: | C31: 1, 2 og 3 | E31: anførte.
A33: Indeholder tilbuddet forbehold: | C33: Nej
A34: Evt. forbehold vedlagt som bilag nr.: | C34: Ingen
A36: Bemyndiget til at føre forhandlinger vedrørende nærværende tilbud, jf. KB er: | C36: Sektionsdirektør
A38: Navn: | B38: Jacob Sanbeck Nielsen
A39: Firma: | B39: Aarsleff Rail A/S
A40: Mail: | B40: jsni@aarsleffrail.com
A41: Tlf.nr.: | B41: 2027 4682
A43: Tilbudsgiverens underskrift er bindende for samtlige angivne priser og oplysninger i øvrigt i det samlede tilbud med tilhørende bilag.
A44: ……………………………….den…………………………………………………………………………………
A46: ………………………………….…………………………………………………………………………………
A47: (Underskrift)

Sheet 3 Spor
A1: Fagpost (FP) Hovedpost (HP) Post (P) Underpost (UP) | B1: Spor | C1: Enhed | D1: Mængde Forberedende arbejder | E1: Mængde Stadie 1 -1.+ 2. hovedspor Htå -Ro spærret | F1: Mængde Stadie 1a | G1: Mængde Stadie 3 – 3. + 4. hovedspor Htå - Ro spærret | H1: Mængde Stadie 3a | I1: Mængde Stadie 2 – 2. + 3. hovedspor Htå – Ro spærret | J1: Mængde Stadie 2a | K1: Mængde Stadie 4 – 1. og 2. hovedspor Høje Taastrup – Roskilde spærret | L1: Mængde Stadie 5 – 1 + 2 hsp Htå – Ro. Maskinelle arbejder på rammeaftale | M1: Mængde Stadie 6 – Afsluttende manuelle arbejder | N1: Mængde Stadie 7 - 3. og 4. hovedspor Høje Taastrup – Roskilde spærret. Manuelle arbejder | O1: Mængde Stadie 7a - 2. hovedspor Høje Taastrup – Roskilde spærret | P1: Mængde Stadie 8 – 3 + 4 hovedspor Htå – Ro Maskinelle arbejder på rammeaftale | Q1: Mængde Stadie 9 - 3. og 4. hovedspor Høje Taastrup – Roskilde spærret. Afsluttende manuelle arbejder | R1: Mængde i alt | S1: Enhedspris DKK | T1: I alt DKK
A2: 3 | B2: Spor | T2: =R2*S2 -> 0
A3: 3.1 | B3: Bygherreleverancer | T3: =R3*S3 -> 0
A4: 3.3 | B4: Sporkonstruktioner | T4: =R4*S4 -> 0
A5: 3.3.6 | B5: Optagning og genindbygning af sporrammer | C5: M | D5: 0 | E5: 492 | F5: 0 | G5: 143 | H5: 0 | I5: 140 | J5: 0 | K5: 0 | L5: 0 | M5: 0 | N5: 0 | O5: 0 | P5: 0 | Q5: 0 | R5: =SUM(D5:Q5) -> 775 | S5: 7494 | T5: =R5*S5 -> 5807850
A6: 3.5 | B6: Svejsearbejder | T6: =R6*S6 -> 0
A7: 3.5.3 | B7: Spændingsudligning | T7: =R7*S7 -> 0
A8: 3.5.3.1 | B8: Spor der kun er ballastrenset / justeret med sideflytning | C8: M | D8: 0 | E8: 0 | F8: 0 | G8: 0 | H8: 0 | I8: 18000 | J8: 0 | K8: 0 | L8: 0 | M8: 0 | N8: 0 | O8: 0 | P8: 0 | Q8: 0 | R8: =SUM(D8:Q8) -> 18000 | S8: 101 | T8: =R8*S8 -> 1818000
A9: 3.6 | B9: Justeringsarbejder | T9: =R9*S9 -> 0
A10: 3.6.3 | B10: Slutjustering spor | C10: M | D10: 0 | E10: 492 | F10: 0 | G10: 143 | H10: 0 | I10: 140 | J10: 0 | K10: 0 | L10: 0 | M10: 0 | N10: 0 | O10: 0 | P10: 0 | Q10: 0 | R10: =SUM(D10:Q10) -> 775 | S10: 1008 | T10: =R10*S10 -> 781200
A11: 3.6.5 | B11: Justering af ikke ombygget spor | C11: M | D11: 0 | E11: 0 | F11: 0 | G11: 0 | H11: 0 | I11: 18000 | J11: 0 | K11: 0 | L11: 0 | M11: 0 | N11: 0 | O11: 0 | P11: 0 | Q11: 0 | R11: =SUM(D11:Q11) -> 18000 | S11: 145 | T11: =R11*S11 -> 2610000
A12: 3.6.6 | B12: Justering af eksisterende sporskifter | C12: STK | D12: 0 | E12: 0 | F12: 0 | G12: 0 | H12: 0 | I12: 4 | J12: 0 | K12: 0 | L12: 0 | M12: 0 | N12: 0 | O12: 0 | P12: 0 | Q12: 0 | R12: =SUM(D12:Q12) -> 4 | S12: 122531 | T12: =R12*S12 -> 490124
A13: 3.6.7 | B13: kørsel med DSM (100.000 bruttoton) | C13: M | D13: 0 | E13: 0 | F13: 0 | G13: 0 | H13: 0 | I13: 18800 | J13: 0 | K13: 0 | L13: 0 | M13: 0 | N13: 0 | O13: 0 | P13: 0 | Q13: 0 | R13: =SUM(D13:Q13) -> 18800 | S13: 17.5 | T13: =R13*S13 -> 329000
A14: 3.6.9 | B14: Belastning af sporbærende broer (25.000 bruttoton) | C14: STK | D14: 0 | E14: 0 | F14: 0 | G14: 0 | H14: 0 | I14: 13 | J14: 0 | K14: 0 | L14: 0 | M14: 0 | N14: 0 | O14: 0 | P14: 0 | Q14: 0 | R14: =SUM(D14:Q14) -> 13 | S14: 16814 | T14: =R14*S14 -> 218582
A15: 3.7 | B15: Øvrige sporarbejder | T15: =R15*S15 -> 0
A16: 3.7.12 | B16: Krabbemåling ved spor- og bro-arbejder | C16: M | D16: 8400 | E16: 0 | F16: 0 | G16: 0 | H16: 0 | I16: 18800 | J16: 0 | K16: 0 | L16: 0 | M16: 0 | N16: 0 | O16: 0 | P16: 0 | Q16: 0 | R16: =SUM(D16:Q16) -> 27200 | S16: 40.5 | T16: =R16*S16 -> 1101600
B18: Samlet tilbudssum ekskl. moms (i DKK) | T18: =SUM(T2:T16) -> 13156356
B19: Overføres til "Hovedtilbudsliste"

Sheet 4 Jord og ballast
A1: Fagpost (FP) Hovedpost (HP) Post (P) Underpost (UP) | B1: Jord og ballast | C1: Enhed | D1: Mængde Forberedende arbejder | E1: Mængde Stadie 1 -1.+ 2. hovedspor Htå -Ro spærret | F1: Mængde Stadie 1a | G1: Mængde Stadie 3 – 3. + 4. hovedspor Htå - Ro spærret | H1: Mængde Stadie 3a | I1: Mængde Stadie 2 – 2. + 3. hovedspor Htå – Ro spærret | J1: Mængde Stadie 2a | K1: Mængde Stadie 4 – 1. og 2. hovedspor Høje Taastrup – Roskilde spærret | L1: Mængde Stadie 5 – 1 + 2 hsp Htå – Ro. Maskinelle arbejder på rammeaftale | M1: Mængde Stadie 6 – Afsluttende manuelle arbejder | N1: Mængde Stadie 7 - 3. og 4. hovedspor Høje Taastrup – Roskilde spærret. Manuelle arbejder | O1: Mængde Stadie 7a - 2. hovedspor Høje Taastrup – Roskilde spærret | P1: Mængde Stadie 8 – 3 + 4 hovedspor Htå – Ro Maskinelle arbejder på rammeaftale | Q1: Mængde Stadie 9 - 3. og 4. hovedspor Høje Taastrup – Roskilde spærret. Afsluttende manuelle arbejder | R1: Mængde i alt | S1: Enhedspris DKK | T1: I alt DKK
A2: 4 | B2: Jord og ballast | T2: =R2*S2 -> 0
A3: 4.1 | B3: Materialer | T3: =R3*S3 -> 0
A4: 4.1.1 | B4: Levering af ballastskærver | C4: M3 | D4: 4 | E4: 84 | F4: 0 | G4: 0 | H4: 0 | I4: 1417 | J4: 0 | K4: 0 | L4: 0 | M4: 0 | N4: 0 | O4: 0 | P4: 0 | Q4: 0 | R4: =SUM(D4:Q4) -> 1505 | S4: 402 | T4: =R4*S4 -> 605010
A5: 4.1.3 | B5: Levering af SGII | C5: M3 | D5: 0 | E5: 257 | F5: 0 | G5: 0 | H5: 0 | I5: 14 | J5: 0 | K5: 0 | L5: 0 | M5: 0 | N5: 0 | O5: 0 | P5: 0 | Q5: 0 | R5: =SUM(D5:Q5) -> 271 | S5: 442 | T5: =R5*S5 -> 119782
A6: 4.1.4 | B6: Levering af veldrænende grus | C6: M3 | D6: 43 | E6: 0 | F6: 0 | G6: 0 | H6: 0 | I6: 10845 | J6: 0 | K6: 0 | L6: 0 | M6: 0 | N6: 0 | O6: 0 | P6: 0 | Q6: 0 | R6: =SUM(D6:Q6) -> 10888 | S6: 252 | T6: =R6*S6 -> 2743776
A7: 4.1.5 | B7: Levering af BLII | C7: M3 | D7: 0 | E7: 244 | F7: 0 | G7: 0 | H7: 0 | I7: 0 | J7: 0 | K7: 0 | L7: 0 | M7: 0 | N7: 0 | O7: 0 | P7: 0 | Q7: 0 | R7: =SUM(D7:Q7) -> 244 | S7: 344 | T7: =R7*S7 -> 83936
A8: 4.1.a | B8: Levering af filtermateriale | C8: M3 | D8: 0 | E8: 0 | F8: 0 | G8: 0 | H8: 0 | I8: 1985 | J8: 0 | K8: 0 | L8: 0 | M8: 0 | N8: 0 | O8: 0 | P8: 0 | Q8: 0 | R8: =SUM(D8:Q8) -> 1985 | S8: 400 | T8: =R8*S8 -> 794000
A9: 4.5 | B9: Råjordsarbejder | T9: =R9*S9 -> 0
A10: 4.6 | B10: Øvrige jord- og ballastarbejder | T10: =R10*S10 -> 0
A11: 4.6.1 | B11: Etablering af brokiler ved sporbærende broer | C11: STK | D11: 0 | E11: 6 | F11: 0 | G11: 6 | H11: 0 | I11: 0 | J11: 0 | K11: 0 | L11: 0 | M11: 0 | N11: 0 | O11: 0 | P11: 0 | Q11: 0 | R11: =SUM(D11:Q11) -> 12 | S11: 18544 | T11: =R11*S11 -> 222528
A12: 4.6.3 | B12: Ballastmåtter på sporbærende broer | C12: M2 | D12: 0 | E12: 135 | F12: 0 | G12: 0 | H12: 0 | I12: 0 | J12: 0 | K12: 0 | L12: 0 | M12: 0 | N12: 0 | O12: 0 | P12: 0 | Q12: 0 | R12: =SUM(D12:Q12) -> 135 | S12: 1509 | T12: =R12*S12 -> 203715
A13: 4.X | B13: Projektspecifikke arbejder ifm. Jord og ballast | T13: =R13*S13 -> 0
A14: 4.X.1 | B14: Reprofilering af skærveballast efter etablering af drænrende mellem spor 2 og 3 | C14: M | D14: 0 | E14: 0 | F14: 0 | G14: 0 | H14: 0 | I14: 16548 | J14: 0 | K14: 0 | L14: 0 | M14: 0 | N14: 0 | O14: 0 | P14: 0 | Q14: 0 | R14: =SUM(D14:Q14) -> 16548 | S14: 37 | T14: =R14*S14 -> 612276
B16: Samlet tilbudssum ekskl. moms (i DKK) | T16: =SUM(T2:T14) -> 5385023
B17: Overføres til "Hovedtilbudsliste"

Sheet 5 Afvanding
A1: Fagpost (FP) Hovedpost (HP) Post (P) Underpost (UP) | B1: Afvanding | C1: Enhed | D1: Mængde Forberedende arbejder | E1: Mængde Stadie 1 -1.+ 2. hovedspor Htå -Ro spærret | F1: Mængde Stadie 1a | G1: Mængde Stadie 3 – 3. + 4. hovedspor Htå - Ro spærret | H1: Mængde Stadie 3a | I1: Mængde Stadie 2 – 2. + 3. hovedspor Htå – Ro spærret | J1: Mængde Stadie 2a | K1: Mængde Stadie 4 – 1. og 2. hovedspor Høje Taastrup – Roskilde spærret | L1: Mængde Stadie 5 – 1 + 2 hsp Htå – Ro. Maskinelle arbejder på rammeaftale | M1: Mængde Stadie 6 – Afsluttende manuelle arbejder | N1: Mængde Stadie 7 - 3. og 4. hovedspor Høje Taastrup – Roskilde spærret. Manuelle arbejder | O1: Mængde Stadie 7a - 2. hovedspor Høje Taastrup – Roskilde spærret | P1: Mængde Stadie 8 – 3 + 4 hovedspor Htå – Ro Maskinelle arbejder på rammeaftale | Q1: Mængde Stadie 9 - 3. og 4. hovedspor Høje Taastrup – Roskilde spærret. Afsluttende manuelle arbejder | R1: Mængde i alt | S1: Enhedspris DKK | T1: I alt DKK
A2: 5 | B2: Afvanding | T2: =R2*S2 -> 0
A3: 5.1 | B3: Etablering af drænsystem | T3: =R3*S3 -> 0
A4: 5.1.1 | B4: Etablering af fuldslidset dræn, dybde ≤ 1 m under råjordsplanum | T4: =R4*S4 -> 0
A5: 5.1.1.1 | B5: Ø160 (Ø145) med filtergrus A, udgravning bredde 0,40 meter | C5: M | D5: 0 | E5: 21 | F5: 0 | G5: 21 | H5: 0 | I5: 829 | J5: 0 | K5: 0 | L5: 0 | M5: 0 | N5: 0 | O5: 0 | P5: 0 | Q5: 0 | R5: =SUM(D5:Q5) -> 871 | S5: 1965 | T5: =R5*S5 -> 1711515
A6: 5.1.1.a | B6: Brokile dræn | C6: M | D6: 0 | E6: 22 | F6: 0 | G6: 0 | H6: 25 | I6: 0 | J6: 0 | K6: 0 | L6: 0 | M6: 0 | N6: 0 | O6: 0 | P6: 0 | Q6: 0 | R6: =SUM(D6:Q6) -> 47 | S6: 4025 | T6: =R6*S6 -> 189175
A7: 5.1.3 | B7: Etablering af topslidset dræn, dybde ≤ 1 m under råjordsplanum | T7: =R7*S7 -> 0
A8: 5.1.3.1 | B8: Ø160 (Ø145) med filtergrus A, udgravning bredde 0,40 meter | C8: M | D8: 0 | E8: 0 | F8: 0 | G8: 0 | H8: 0 | I8: 1818 | J8: 0 | K8: 0 | L8: 0 | M8: 0 | N8: 0 | O8: 0 | P8: 0 | Q8: 0 | R8: =SUM(D8:Q8) -> 1818 | S8: 2065 | T8: =R8*S8 -> 3754170
A9: 5.1.3.2 | B9: Ø200 (Ø180) med filtergrus A, udgravning bredde 0,60 meter | C9: M | D9: 0 | E9: 0 | F9: 0 | G9: 0 | H9: 0 | I9: 2067 | J9: 0 | K9: 0 | L9: 0 | M9: 0 | N9: 0 | O9: 0 | P9: 0 | Q9: 0 | R9: =SUM(D9:Q9) -> 2067 | S9: 2864 | T9: =R9*S9 -> 5919888
A10: 5.1.3.3 | B10: Ø250 med filtergrus A, udgravning bredde 0,60 meter | C10: M | D10: 0 | E10: 0 | F10: 0 | G10: 0 | H10: 0 | I10: 1960 | J10: 0 | K10: 0 | L10: 0 | M10: 0 | N10: 0 | O10: 0 | P10: 0 | Q10: 0 | R10: =SUM(D10:Q10) -> 1960 | S10: 3042 | T10: =R10*S10 -> 5962320
A11: 5.1.3.4 | B11: Ø315 med filtergrus A, udgravning bredde 0,60 meter | C11: M | D11: 0 | E11: 0 | F11: 0 | G11: 0 | H11: 0 | I11: 1197 | J11: 0 | K11: 0 | L11: 0 | M11: 0 | N11: 0 | O11: 0 | P11: 0 | Q11: 0 | R11: =SUM(D11:Q11) -> 1197 | S11: 3471 | T11: =R11*S11 -> 4154787
A12: 5.2 | B12: Etablering af tætte ledninger og trykledning | T12: =R12*S12 -> 0
A13: 5.2.1 | B13: Etablering af tætte ledninger, dybde ≤ 1 m under råjordsplanrum | T13: =R13*S13 -> 0
A14: 5.2.1.1 | B14: Ø160 PP/PE | C14: M | D14: 0 | E14: 26 | F14: 0 | G14: 7 | H14: 0 | I14: 451 | J14: 0 | K14: 0 | L14: 0 | M14: 0 | N14: 0 | O14: 0 | P14: 0 | Q14: 0 | R14: =SUM(D14:Q14) -> 484 | S14: 2463 | T14: =R14*S14 -> 1192092
A15: 5.2.1.2 | B15: Ø200 PP/PE | C15: M | D15: 0 | E15: 0 | F15: 0 | G15: 0 | H15: 0 | I15: 203 | J15: 0 | K15: 0 | L15: 0 | M15: 0 | N15: 0 | O15: 0 | P15: 0 | Q15: 0 | R15: =SUM(D15:Q15) -> 203 | S15: 2945 | T15: =R15*S15 -> 597835
A16: 5.2.1.3 | B16: Ø250 PP/PE | C16: M | D16: 0 | E16: 24 | F16: 0 | G16: 0 | H16: 0 | I16: 212 | J16: 0 | K16: 0 | L16: 0 | M16: 0 | N16: 0 | O16: 0 | P16: 0 | Q16: 0 | R16: =SUM(D16:Q16) -> 236 | S16: 3007 | T16: =R16*S16 -> 709652
A17: 5.2.1.4 | B17: Ø315 PP/PE | C17: M | D17: 0 | E17: 109 | F17: 0 | G17: 0 | H17: 0 | I17: 191 | J17: 0 | K17: 0 | L17: 0 | M17: 0 | N17: 0 | O17: 0 | P17: 0 | Q17: 0 | R17: =SUM(D17:Q17) -> 300 | S17: 3392 | T17: =R17*S17 -> 1017600
A18: 5.2.1.5 | B18: Ø400 PP/PE | C18: M | D18: 0 | E18: 11 | F18: 0 | G18: 0 | H18: 0 | I18: 2 | J18: 0 | K18: 0 | L18: 0 | M18: 0 | N18: 0 | O18: 0 | P18: 0 | Q18: 0 | R18: =SUM(D18:Q18) -> 13 | S18: 4240 | T18: =R18*S18 -> 55120
A19: 5.2.6 | B19: Tillægspris ved ledningspassager ved køreledningsmaster, bardunpæle og andre objekter | T19: =R19*S19 -> 0
A20: 5.2.6.1 | B20: Kørestrømsmast | C20: STK | D20: 0 | E20: 0 | F20: 0 | G20: 0 | H20: 0 | I20: 148 | J20: 0 | K20: 0 | L20: 0 | M20: 0 | N20: 0 | O20: 0 | P20: 0 | Q20: 0 | R20: =SUM(D20:Q20) -> 148 | S20: 2861 | T20: =R20*S20 -> 423428
A21: 5.2.6.2 | B21: Kørestrømsmast og bardunfundament | C21: STK | D21: 0 | E21: 0 | F21: 0 | G21: 0 | H21: 0 | I21: 29 | J21: 0 | K21: 0 | L21: 0 | M21: 0 | N21: 0 | O21: 0 | P21: 0 | Q21: 0 | R21: =SUM(D21:Q21) -> 29 | S21: 2861 | T21: =R21*S21 -> 82969
A22: 5.3 | B22: Etablering af gennemløbsbrønde | T22: =R22*S22 -> 0
A23: 5.3.1 | B23: Etablering af gennemløbsbrønde dybde ≤ 1 m under råjordsplanum | T23: =R23*S23 -> 0
A24: 5.3.1.2 | B24: Ø425 PP | C24: STK | D24: 0 | E24: 0 | F24: 0 | G24: 0 | H24: 0 | I24: 157 | J24: 0 | K24: 0 | L24: 0 | M24: 0 | N24: 0 | O24: 0 | P24: 0 | Q24: 0 | R24: =SUM(D24:Q24) -> 157 | S24: 3923 | T24: =R24*S24 -> 615911
A25: 5.3.1.3 | B25: Ø600 PP | C25: STK | D25: 0 | E25: 0 | F25: 0 | G25: 0 | H25: 0 | I25: 82 | J25: 0 | K25: 0 | L25: 0 | M25: 0 | N25: 0 | O25: 0 | P25: 0 | Q25: 0 | R25: =SUM(D25:Q25) -> 82 | S25: 6257 | T25: =R25*S25 -> 513074
A26: 5.3.1.a | B26: Ø1000 Bt | C26: STK | D26: 0 | E26: 0 | F26: 0 | G26: 0 | H26: 0 | I26: 1 | J26: 0 | K26: 0 | L26: 0 | M26: 0 | N26: 0 | O26: 0 | P26: 0 | Q26: 0 | R26: =SUM(D26:Q26) -> 1 | S26: 25501 | T26: =R26*S26 -> 25501
A27: 5.4 | B27: Etablering af sandfangsbrønde | T27: =R27*S27 -> 0
A28: 5.4.1 | B28: Etablering af sandfangsbrønde dybde ≤ 1 m under råjordsplanum | T28: =R28*S28 -> 0
A29: 5.4.1.3 | B29: Ø600 PP | C29: STK | D29: 4 | E29: 0 | F29: 0 | G29: 0 | H29: 0 | I29: 5 | J29: 0 | K29: 0 | L29: 0 | M29: 0 | N29: 0 | O29: 0 | P29: 0 | Q29: 0 | R29: =SUM(D29:Q29) -> 9 | S29: 8043 | T29: =R29*S29 -> 72387
A30: 5.4.1.a | B30: Ø800 PP | C30: STK | D30: 1 | E30: 0 | F30: 0 | G30: 0 | H30: 0 | I30: 1 | J30: 0 | K30: 0 | L30: 0 | M30: 0 | N30: 0 | O30: 0 | P30: 0 | Q30: 0 | R30: =SUM(D30:Q30) -> 2 | S30: 19060 | T30: =R30*S30 -> 38120
A31: 5.4.2 | B31: Etablering af sandfangsbrønde 1 m < dybde ≤ 2 m under råjordsplanum | T31: =R31*S31 -> 0
A32: 5.4.2.2 | B32: Ø600 PP | C32: STK | D32: 6 | E32: 0 | F32: 0 | G32: 0 | H32: 0 | I32: 0 | J32: 0 | K32: 0 | L32: 0 | M32: 0 | N32: 0 | O32: 0 | P32: 0 | Q32: 0 | R32: =SUM(D32:Q32) -> 6 | S32: 15312 | T32: =R32*S32 -> 91872
A33: 5.4.2.a | B33: Ø800 PP | C33: STK | D33: 3 | E33: 0 | F33: 0 | G33: 0 | H33: 0 | I33: 1 | J33: 0 | K33: 0 | L33: 0 | M33: 0 | N33: 0 | O33: 0 | P33: 0 | Q33: 0 | R33: =SUM(D33:Q33) -> 4 | S33: 22731 | T33: =R33*S33 -> 90924
A34: 5.6 | B34: Banegrøfter | T34: =R34*S34 -> 0
A35: 5.6.1 | B35: Oprensning af banegrøfter | C35: M | D35: 0 | E35: 190 | F35: 0 | G35: 31 | H35: 0 | I35: 0 | J35: 0 | K35: 0 | L35: 0 | M35: 0 | N35: 0 | O35: 0 | P35: 0 | Q35: 0 | R35: =SUM(D35:Q35) -> 221 | S35: 179 | T35: =R35*S35 -> 39559
A36: 5.6.2 | B36: Etablering af fliseseng lille. | C36: STK | D36: 0 | E36: 5 | F36: 0 | G36: 0 | H36: 0 | I36: 0 | J36: 0 | K36: 0 | L36: 0 | M36: 0 | N36: 0 | O36: 0 | P36: 0 | Q36: 0 | R36: =SUM(D36:Q36) -> 5 | S36: 24162 | T36: =R36*S36 -> 120810
A37: 5.6.3 | B37: Etablering af fliseseng stor | C37: STK | D37: 0 | E37: 11 | F37: 0 | G37: 0 | H37: 0 | I37: 0 | J37: 0 | K37: 0 | L37: 0 | M37: 0 | N37: 0 | O37: 0 | P37: 0 | Q37: 0 | R37: =SUM(D37:Q37) -> 11 | S37: 36374 | T37: =R37*S37 -> 400114
A38: 5.7 | B38: Gravekasse | T38: =R38*S38 -> 0
A39: 5.7.a | B39: Gravekasse ift. eksisterende terræn | C39: M | D39: 0 | E39: 188 | F39: 0 | G39: 27 | H39: 0 | I39: 8929 | J39: 0 | K39: 0 | L39: 0 | M39: 0 | N39: 0 | O39: 0 | P39: 0 | Q39: 0 | R39: =SUM(D39:Q39) -> 9144 | S39: 344 | T39: =R39*S39 -> 3145536
A40: 5.7.b | B40: Gravekasse ift. eksisterende terræn d < 2m | C40: M | D40: 30 | E40: 0 | F40: 0 | G40: 0 | H40: 0 | I40: 250 | J40: 0 | K40: 0 | L40: 0 | M40: 0 | N40: 0 | O40: 0 | P40: 0 | Q40: 0 | R40: =SUM(D40:Q40) -> 280 | S40: 1183 | T40: =R40*S40 -> 331240
...

Sheet 6 Kabelomlægning og føringsveje
A1: Fagpost (FP) Hovedpost (HP) Post (P) Underpost (UP) | B1: Kabelomlægning og føringsveje | C1: Enhed | D1: Mængde Forberedende arbejder | E1: Mængde Stadie 1 -1.+ 2. hovedspor Htå -Ro spærret | F1: Mængde Stadie 1a | G1: Mængde Stadie 3 – 3. + 4. hovedspor Htå - Ro spærret | H1: Mængde Stadie 3a | I1: Mængde Stadie 2 – 2. + 3. hovedspor Htå – Ro spærret | J1: Mængde Stadie 2a | K1: Mængde Stadie 4 – 1. og 2. hovedspor Høje Taastrup – Roskilde spærret | L1: Mængde Stadie 5 – 1 + 2 hsp Htå – Ro. Maskinelle arbejder på rammeaftale | M1: Mængde Stadie 6 – Afsluttende manuelle arbejder | N1: Mængde Stadie 7 - 3. og 4. hovedspor Høje Taastrup – Roskilde spærret. Manuelle arbejder | O1: Mængde Stadie 7a - 2. hovedspor Høje Taastrup – Roskilde spærret | P1: Mængde Stadie 8 – 3 + 4 hovedspor Htå – Ro Maskinelle arbejder på rammeaftale | Q1: Mængde Stadie 9 - 3. og 4. hovedspor Høje Taastrup – Roskilde spærret. Afsluttende manuelle arbejder | R1: Mængde i alt | S1: Enhedspris DKK | T1: I alt DKK
A2: 6 | B2: Kabelomlægning og føringsveje | T2: =R2*S2 -> 0
B3: Kabelomlægning | T3: =R3*S3 -> 0
A4: 6.2.2 | B4: Opgravning af eksisterende kabler på fri strækning | C4: M | D4: 0 | E4: 435 | F4: 0 | G4: 20 | H4: 0 | I4: 35 | J4: 0 | K4: 0 | L4: 0 | M4: 0 | N4: 0 | O4: 0 | P4: 0 | Q4: 0 | R4: =SUM(D4:Q4) -> 490 | S4: 256 | T4: =R4*S4 -> 125440
A5: 6.2.4 | B5: Optagning af eksisterende kabler i kabelrender | T5: =R5*S5 -> 0
A6: 6.2.4.1 | B6: Kabelrende med 1-10 kabler | C6: M | D6: 0 | E6: 480 | F6: 0 | G6: 9140 | H6: 0 | I6: 0 | J6: 0 | K6: 0 | L6: 0 | M6: 0 | N6: 0 | O6: 0 | P6: 0 | Q6: 0 | R6: =SUM(D6:Q6) -> 9620 | S6: 118 | T6: =R6*S6 -> 1135160
A7: 6.2.6 | B7: Nedgravning af eksisterende/nye kabler på fri strækning | C7: M | D7: 0 | E7: 0 | F7: 0 | G7: 0 | H7: 0 | I7: 0 | J7: 0 | K7: 0 | L7: 0 | M7: 435 | N7: 0 | O7: 0 | P7: 0 | Q7: 55 | R7: =SUM(D7:Q7) -> 490 | S7: 1484 | T7: =R7*S7 -> 727160
A8: 6.2.8 | B8: Lægning af eksisterende/nye kabler i kabelrender | T8: =R8*S8 -> 0
A9: 6.2.8.1 | B9: Kabelrende med 1-10 kabler | C9: M | D9: 0 | E9: 0 | F9: 0 | G9: 0 | H9: 0 | I9: 0 | J9: 0 | K9: 0 | L9: 0 | M9: 82 | N9: 0 | O9: 0 | P9: 0 | Q9: 1960 | R9: =SUM(D9:Q9) -> 2042 | S9: 106 | T9: =R9*S9 -> 216452
A10: 6.3 | B10: Optagning af føringsveje | T10: =R10*S10 -> 0
A11: 6.3.1 | B11: Optagning af kabelrender | T11: =R11*S11 -> 0
A12: 6.3.1.4 | B12: Betonkabelrender til deponi | C12: M | D12: 0 | E12: 480 | F12: 0 | G12: 9140 | H12: 0 | I12: 0 | J12: 0 | K12: 0 | L12: 0 | M12: 0 | N12: 0 | O12: 0 | P12: 0 | Q12: 0 | R12: =SUM(D12:Q12) -> 9620 | S12: 44 | T12: =R12*S12 -> 423280
A13: 6.4 | B13: Etablering af føringsveje (kabelrender) | T13: =R13*S13 -> 0
A14: 6.4.1 | B14: Levering af nye kabelrender | T14: =R14*S14 -> 0
A15: 6.4.1.6 | B15: Plast 25-43 cm | C15: M | D15: 0 | E15: 0 | F15: 0 | G15: 0 | H15: 0 | I15: 0 | J15: 0 | K15: 0 | L15: 0 | M15: 82 | N15: 0 | O15: 0 | P15: 0 | Q15: 1960 | R15: =SUM(D15:Q15) -> 2042 | S15: 5 | T15: =R15*S15 -> 10210
A16: 6.4.2 | B16: Levering af monteringssystem for kabelrender | C16: M | D16: 0 | E16: 0 | F16: 0 | G16: 0 | H16: 0 | I16: 0 | J16: 0 | K16: 0 | L16: 0 | M16: 0 | N16: 0 | O16: 0 | P16: 0 | Q16: 4 | R16: =SUM(D16:Q16) -> 4 | S16: 559 | T16: =R16*S16 -> 2236
A17: 6.4.3 | B17: Etablering af kabelrender | T17: =R17*S17 -> 0
A18: 6.4.3.6 | B18: Plast 25-43 cm | C18: M | D18: 0 | E18: 0 | F18: 0 | G18: 0 | H18: 0 | I18: 0 | J18: 0 | K18: 0 | L18: 0 | M18: 82 | N18: 0 | O18: 0 | P18: 0 | Q18: 1960 | R18: =SUM(D18:Q18) -> 2042 | S18: 230 | T18: =R18*S18 -> 469660
A19: 6.8 | B19: Øvrige arbejder i forbindelse med kabelomlægning og føringsveje | T19: =R19*S19 -> 0
A20: 6.8.1 | B20: Etablering af klikrør om eksisterende kabler | C20: M | D20: 0 | E20: 0 | F20: 0 | G20: 0 | H20: 0 | I20: 0 | J20: 0 | K20: 0 | L20: 0 | M20: 398 | N20: 0 | O20: 0 | P20: 0 | Q20: 7430 | R20: =SUM(D20:Q20) -> 7828 | S20: 363 | T20: =R20*S20 -> 2841564
B22: Samlet tilbudssum ekskl. moms (i DKK) | T22: =SUM(T2:T20) -> 5951162
B23: Overføres til "Hovedtilbudsliste"

Sheet 8 Perroner
A1: Fagpost (FP) Hovedpost (HP) Post (P) Underpost (UP) | B1: Perroner | C1: Enhed | D1: Mængde Forberedende arbejder | E1: Mængde Stadie 1 -1.+ 2. hovedspor Htå -Ro spærret | F1: Mængde Stadie 1a | G1: Mængde Stadie 3 – 3. + 4. hovedspor Htå - Ro spærret | H1: Mængde Stadie 3a | I1: Mængde Stadie 2 – 2. + 3. hovedspor Htå – Ro spærret | J1: Mængde Stadie 2a | K1: Mængde Stadie 4 – 1. og 2. hovedspor Høje Taastrup – Roskilde spærret | L1: Mængde Stadie 5 – 1 + 2 hsp Htå – Ro. Maskinelle arbejder på rammeaftale | M1: Mængde Stadie 6 – Afsluttende manuelle arbejder | N1: Mængde Stadie 7 - 3. og 4. hovedspor Høje Taastrup – Roskilde spærret. Manuelle arbejder | O1: Mængde Stadie 7a - 2. hovedspor Høje Taastrup – Roskilde spærret | P1: Mængde Stadie 8 – 3 + 4 hovedspor Htå – Ro Maskinelle arbejder på rammeaftale | Q1: Mængde Stadie 9 - 3. og 4. hovedspor Høje Taastrup – Roskilde spærret. Afsluttende manuelle arbejder | R1: Mængde i alt | S1: Enhedspris DKK | T1: I alt DKK
A2: 8 | B2: Perroner | T2: =R2*S2 -> 0
A3: 8.1 | B3: Forberedende arbejder | T3: =R3*S3 -> 0
A4: 8.1.1 | B4: Rydning af perronarealer | C4: SUM | D4: 0 | E4: 1 | F4: 0 | G4: 0 | H4: 0 | I4: 0 | J4: 0 | K4: 0 | L4: 0 | M4: 0 | N4: 0 | O4: 0 | P4: 0 | Q4: 0 | R4: =SUM(D4:Q4) -> 1 | S4: 42225 | T4: =R4*S4 -> 42225
A5: 8.1.3 | B5: Optagning og genudlægning af eksisterende flisebelægning | C5: M2 | D5: 0 | E5: 701 | F5: 0 | G5: 0 | H5: 0 | I5: 0 | J5: 0 | K5: 0 | L5: 0 | M5: 0 | N5: 0 | O5: 0 | P5: 0 | Q5: 0 | R5: =SUM(D5:Q5) -> 701 | S5: 889 | T5: =R5*S5 -> 623189
A6: 8.1.5 | B6: Midlertidigt hegn på eksisterende perronner der ombygges | C6: M | D6: 0 | E6: 258 | F6: 0 | G6: 0 | H6: 0 | I6: 0 | J6: 0 | K6: 0 | L6: 0 | M6: 0 | N6: 0 | O6: 0 | P6: 0 | Q6: 0 | R6: =SUM(D6:Q6) -> 258 | S6: 221 | T6: =R6*S6 -> 57018
A7: 8.1.a | B7: Prøvegravning | C7: STK | D7: 4 | E7: 0 | F7: 0 | G7: 0 | H7: 0 | I7: 0 | J7: 0 | K7: 0 | L7: 0 | M7: 0 | N7: 0 | O7: 0 | P7: 0 | Q7: 0 | R7: =SUM(D7:Q7) -> 4 | S7: 1190 | T7: =R7*S7 -> 4760
A8: 8.2 | B8: Tilpasning af perronforkanter | T8: =R8*S8 -> 0
A9: 8.2.2 | B9: Opretning af perronforkanter | C9: M | D9: 0 | E9: 252 | F9: 0 | G9: 0 | H9: 0 | I9: 0 | J9: 0 | K9: 0 | L9: 0 | M9: 0 | N9: 0 | O9: 0 | P9: 0 | Q9: 0 | R9: =SUM(D9:Q9) -> 252 | S9: 2055 | T9: =R9*S9 -> 517860
A10: 8.X | B10: Projektspecifikke arbejder ifm. Perroner | T10: =R10*S10 -> 0
A11: 8.X.1 | B11: Afstribningslinje | C11: M | D11: 0 | E11: 252 | F11: 0 | G11: 0 | H11: 0 | I11: 0 | J11: 0 | K11: 0 | L11: 0 | M11: 0 | N11: 0 | O11: 0 | P11: 0 | Q11: 0 | R11: =SUM(D11:Q11) -> 252 | S11: 383 | T11: =R11*S11 -> 96516
A12: 8.X.2 | B12: Fremstilling og levering af harlekinoverplader | C12: STK | D12: 0 | E12: 10 | F12: 0 | G12: 0 | H12: 0 | I12: 0 | J12: 0 | K12: 0 | L12: 0 | M12: 0 | N12: 0 | O12: 0 | P12: 0 | Q12: 0 | R12: =SUM(D12:Q12) -> 10 | S12: 8261 | T12: =R12*S12 -> 82610
B14: Samlet tilbudssum ekskl. moms (i DKK) | T14: =SUM(T2:T12) -> 1424178
B15: Overføres til "Hovedtilbudsliste"

Sheet 9 Kørestrøm
A1: Fagpost (FP) Hovedpost (HP) Post (P) Underpost (UP) | B1: Kørestrøm | C1: Enhed | D1: Mængde Forberedende arbejder | E1: Mængde Stadie 1 -1.+ 2. hovedspor Htå -Ro spærret | F1: Mængde Stadie 1a | G1: Mængde Stadie 3 – 3. + 4. hovedspor Htå - Ro spærret | H1: Mængde Stadie 3a | I1: Mængde Stadie 2 – 2. + 3. hovedspor Htå – Ro spærret | J1: Mængde Stadie 2a | K1: Mængde Stadie 4 – 1. og 2. hovedspor Høje Taastrup – Roskilde spærret | L1: Mængde Stadie 5 – 1 + 2 hsp Htå – Ro. Maskinelle arbejder på rammeaftale | M1: Mængde Stadie 6 – Afsluttende manuelle arbejder | N1: Mængde Stadie 7 - 3. og 4. hovedspor Høje Taastrup – Roskilde spærret. Manuelle arbejder | O1: Mængde Stadie 7a - 2. hovedspor Høje Taastrup – Roskilde spærret | P1: Mængde Stadie 8 – 3 + 4 hovedspor Htå – Ro Maskinelle arbejder på rammeaftale | Q1: Mængde Stadie 9 - 3. og 4. hovedspor Høje Taastrup – Roskilde spærret. Afsluttende manuelle arbejder | R1: Mængde i alt | S1: Enhedspris DKK | T1: I alt DKK
A2: 9 | B2: Kørestrøm | T2: =R2*S2 -> 0
A3: 9.1 | B3: Fundering | T3: =R3*S3 -> 0
A4: 9.1.1 | B4: Afsætning af fundament | C4: STK | D4: 8 | E4: 0 | F4: 0 | G4: 0 | H4: 0 | I4: 2 | J4: 0 | K4: 0 | L4: 0 | M4: 0 | N4: 0 | O4: 0 | P4: 0 | Q4: 0 | R4: =SUM(D4:Q4) -> 10 | S4: 405 | T4: =R4*S4 -> 4050
A5: 9.1.2 | B5: Prøvegravning kørestrømsfundament | T5: =R5*S5 -> 0
A6: 9.1.2.2 | B6: Stampet pæl | C6: STK | D6: 8 | E6: 0 | F6: 0 | G6: 0 | H6: 0 | I6: 0 | J6: 0 | K6: 0 | L6: 0 | M6: 0 | N6: 0 | O6: 0 | P6: 0 | Q6: 0 | R6: =SUM(D6:Q6) -> 8 | S6: 5158 | T6: =R6*S6 -> 41264
A7: 9.1.3 | B7: Afhentning af pæle | C7: STK | D7: 8 | E7: 0 | F7: 0 | G7: 0 | H7: 0 | I7: 0 | J7: 0 | K7: 0 | L7: 0 | M7: 0 | N7: 0 | O7: 0 | P7: 0 | Q7: 0 | R7: =SUM(D7:Q7) -> 8 | S7: 2735 | T7: =R7*S7 -> 21880
A8: 9.1.4 | B8: Udlægning og fundering af pæl | T8: =R8*S8 -> 0
A9: 9.1.4.3 | B9: EP-B1 5,5 - 6 m længde | C9: STK | D9: 8 | E9: 0 | F9: 0 | G9: 0 | H9: 0 | I9: 0 | J9: 0 | K9: 0 | L9: 0 | M9: 0 | N9: 0 | O9: 0 | P9: 0 | Q9: 0 | R9: =SUM(D9:Q9) -> 8 | S9: 63732 | T9: =R9*S9 -> 509856
A10: 9.1.4.11 | B10: EP-B14 5,5 - 6 m længde | C10: STK | D10: 0 | E10: 0 | F10: 0 | G10: 0 | H10: 0 | I10: 0 | J10: 0 | K10: 8 | L10: 0 | M10: 0 | N10: 0 | O10: 0 | P10: 0 | Q10: 0 | R10: =SUM(D10:Q10) -> 8 | S10: 57060 | T10: =R10*S10 -> 456480
A11: 9.1.5 | B11: Afstivning/aflastning af eksisterende mast iht. Gravetilladelse | C11: N/A | D11: 0 | E11: 0 | F11: 0 | G11: 0 | H11: 0 | I11: 0 | J11: 0 | K11: 0 | L11: 0 | M11: 0 | N11: 0 | O11: 0 | P11: 0 | Q11: 0 | R11: =SUM(D11:Q11) -> 0 | S11: 0 | T11: =R11*S11 -> 0
A12: 9.1.5.1 | B12: Før-/efter indmålinger af eksisterende mast | C12: STK | D12: 174 | E12: 0 | F12: 0 | G12: 0 | H12: 0 | I12: 0 | J12: 0 | K12: 0 | L12: 0 | M12: 0 | N12: 0 | O12: 0 | P12: 0 | Q12: 0 | R12: =SUM(D12:Q12) -> 174 | S12: 279 | T12: =R12*S12 -> 48546
A13: 9.1.5.2 | B13: Midlertidig aflastning af køreledning - (metode 1) | C13: STK | D13: 0 | E13: 0 | F13: 0 | G13: 0 | H13: 0 | I13: 100 | J13: 0 | K13: 0 | L13: 0 | M13: 0 | N13: 0 | O13: 0 | P13: 0 | Q13: 0 | R13: =SUM(D13:Q13) -> 100 | S13: 6533 | T13: =R13*S13 -> 653300
A14: 9.1.5.3 | B14: Midlertidig afstivning med nødbardun på langs af sporet - (metode 2) | C14: STK | D14: 0 | E14: 0 | F14: 0 | G14: 0 | H14: 0 | I14: 50 | J14: 0 | K14: 0 | L14: 0 | M14: 0 | N14: 0 | O14: 0 | P14: 0 | Q14: 0 | R14: =SUM(D14:Q14) -> 50 | S14: 14482 | T14: =R14*S14 -> 724100
A15: 9.1.5.4 | B15: Midlertidig afstivning mod skinnen på tværs af sporet - (metode 3) | C15: STK | D15: 0 | E15: 0 | F15: 0 | G15: 0 | H15: 0 | I15: 10 | J15: 0 | K15: 0 | L15: 0 | M15: 0 | N15: 0 | O15: 0 | P15: 0 | Q15: 0 | R15: =SUM(D15:Q15) -> 10 | S15: 15663 | T15: =R15*S15 -> 156630
A16: 9.1.6 | B16: Indmåling af udført fundament | C16: STK | D16: 8 | E16: 0 | F16: 0 | G16: 0 | H16: 0 | I16: 0 | J16: 0 | K16: 0 | L16: 0 | M16: 0 | N16: 0 | O16: 0 | P16: 0 | Q16: 0 | R16: =SUM(D16:Q16) -> 8 | S16: 419 | T16: =R16*S16 -> 3352
A17: 9.2 | B17: Stålkonstruktioner | T17: =R17*S17 -> 0
A18: 9.2.4 | B18: Montage af mast | C18: STK | D18: 8 | E18: 0 | F18: 0 | G18: 0 | H18: 0 | I18: 0 | J18: 0 | K18: 0 | L18: 0 | M18: 0 | N18: 0 | O18: 0 | P18: 0 | Q18: 0 | R18: =SUM(D18:Q18) -> 8 | S18: 7069 | T18: =R18*S18 -> 56552
A19: 9.2.5 | B19: Montage af overligger eller bom | C19: STK | D19: 6 | E19: 0 | F19: 0 | G19: 0 | H19: 0 | I19: 0 | J19: 0 | K19: 1 | L19: 0 | M19: 0 | N19: 0 | O19: 0 | P19: 0 | Q19: 0 | R19: =SUM(D19:Q19) -> 7 | S19: 25573 | T19: =R19*S19 -> 179011
A20: 9.2.a | B20: Levering af Ståldele til Rammer | C20: SUM | D20: 1 | E20: 0 | F20: 0 | G20: 0 | H20: 0 | I20: 0 | J20: 0 | K20: 0 | L20: 0 | M20: 0 | N20: 0 | O20: 0 | P20: 0 | Q20: 0 | R20: =SUM(D20:Q20) -> 1 | S20: 694535 | T20: =R20*S20 -> 694535
A21: 9.4 | B21: Master og beslag på eksisterende konstruktioner | T21: =R21*S21 -> 0
A22: 9.4.1 | B22: Levering og montage af beslag på bro | T22: =R22*S22 -> 0
A23: 9.5 | B23: Ophæng | T23: =R23*S23 -> 0
A24: 9.5.1 | B24: Levering og fremstilling af K-ophæng | C24: STK | D24: 0 | E24: 0 | F24: 0 | G24: 7 | H24: 0 | I24: 16 | J24: 0 | K24: 10 | L24: 0 | M24: 0 | N24: 0 | O24: 0 | P24: 0 | Q24: 0 | R24: =SUM(D24:Q24) -> 33 | S24: 3041 | T24: =R24*S24 -> 100353
A25: 9.5.2 | B25: Montage og indregulering af K-ophæng | C25: STK | D25: 0 | E25: 0 | F25: 0 | G25: 7 | H25: 0 | I25: 16 | J25: 0 | K25: 10 | L25: 0 | M25: 0 | N25: 0 | O25: 0 | P25: 0 | Q25: 0 | R25: =SUM(D25:Q25) -> 33 | S25: 6624 | T25: =R25*S25 -> 218592
A26: 9.5.3 | B26: Demontage og bortskaffelse af K-ophæng | T26: =R26*S26 -> 0
A27: 9.5.3.1 | B27: K-ophæng | C27: STK | D27: 0 | E27: 0 | F27: 0 | G27: 23 | H27: 0 | I27: 0 | J27: 0 | K27: 10 | L27: 0 | M27: 0 | N27: 0 | O27: 0 | P27: 0 | Q27: 0 | R27: =SUM(D27:Q27) -> 33 | S27: 3312 | T27: =R27*S27 -> 109296
A28: 9.5.4 | B28: Justering og indregulering af K-ophæng | C28: STK | D28: 0 | E28: 194 | F28: 0 | G28: 194 | H28: 0 | I28: 388 | J28: 0 | K28: 0 | L28: 0 | M28: 0 | N28: 0 | O28: 0 | P28: 0 | Q28: 0 | R28: =SUM(D28:Q28) -> 776 | S28: 3280 | T28: =R28*S28 -> 2545280
A29: 9.6 | B29: Ledningsadskillere | T29: =R29*S29 -> 0
A30: 9.6.1 | B30: Indbygning af ikke bekørbar ledningsadskillelse | C30: STK | D30: 0 | E30: 0 | F30: 0 | G30: 0 | H30: 0 | I30: 0 | J30: 0 | K30: 1 | L30: 0 | M30: 0 | N30: 1 | O30: 0 | P30: 0 | Q30: 0 | R30: =SUM(D30:Q30) -> 2 | S30: 13051 | T30: =R30*S30 -> 26102
A31: 9.6.5 | B31: Udbygning og bortskaffelse af ledningsadskiller, alle typer | C31: STK | D31: 0 | E31: 0 | F31: 0 | G31: 0 | H31: 0 | I31: 0 | J31: 0 | K31: 0 | L31: 0 | M31: 1 | N31: 0 | O31: 0 | P31: 0 | Q31: 1 | R31: =SUM(D31:Q31) -> 2 | S31: 6526 | T31: =R31*S31 -> 13052
A32: 9.8 | B32: Retur- og forstærkningsledninger, samt negativ feeder | T32: =R32*S32 -> 0
A33: 9.8.1 | B33: Overflytning af returleder, forstærkningsleder eller negativ feeder | C33: M | D33: 40 | E33: 0 | F33: 0 | G33: 0 | H33: 0 | I33: 0 | J33: 0 | K33: 0 | L33: 0 | M33: 0 | N33: 0 | O33: 0 | P33: 0 | Q33: 0 | R33: =SUM(D33:Q33) -> 40 | S33: 257 | T33: =R33*S33 -> 10280
A34: 9.8.2 | B34: Montage af returleder | C34: M | D34: 0 | E34: 0 | F34: 0 | G34: 0 | H34: 0 | I34: 0 | J34: 0 | K34: 120 | L34: 0 | M34: 0 | N34: 0 | O34: 0 | P34: 0 | Q34: 0 | R34: =SUM(D34:Q34) -> 120 | S34: 54 | T34: =R34*S34 -> 6480
A35: 9.8.3 | B35: Demontage og bortskaffelse af returleder/forstærkningsleder | C35: M | D35: 0 | E35: 0 | F35: 0 | G35: 0 | H35: 0 | I35: 0 | J35: 0 | K35: 60 | L35: 0 | M35: 0 | N35: 0 | O35: 0 | P35: 0 | Q35: 0 | R35: =SUM(D35:Q35) -> 60 | S35: 28 | T35: =R35*S35 -> 1680
A36: 9.12 | B36: Returstrøm | T36: =R36*S36 -> 0
A37: 9.12.1 | B37: Kabelleverance Alu | T37: =R37*S37 -> 0
A38: 9.12.1.1 | B38: 1x70 mm2 (F) | C38: M | D38: 0 | E38: 0 | F38: 0 | G38: 0 | H38: 0 | I38: 0 | J38: 0 | K38: 50 | L38: 0 | M38: 0 | N38: 0 | O38: 0 | P38: 0 | Q38: 0 | R38: =SUM(D38:Q38) -> 50 | S38: 42 | T38: =R38*S38 -> 2100
A39: 9.13 | B39: Potentialudligning | T39: =R39*S39 -> 0
A40: 9.13.1 | B40: Kabelleverance Alu | T40: =R40*S40 -> 0
...

Sheet 10 Sikring
A1: Fagpost (FP) Hovedpost (HP) Post (P) Underpost (UP) | B1: Sikring | C1: Enhed | D1: Mængde Forberedende arbejder | E1: Mængde Stadie 1 -1.+ 2. hovedspor Htå -Ro spærret | F1: Mængde Stadie 1a | G1: Mængde Stadie 3 – 3. + 4. hovedspor Htå - Ro spærret | H1: Mængde Stadie 3a | I1: Mængde Stadie 2 – 2. + 3. hovedspor Htå – Ro spærret | J1: Mængde Stadie 2a | K1: Mængde Stadie 4 – 1. og 2. hovedspor Høje Taastrup – Roskilde spærret | L1: Mængde Stadie 5 – 1 + 2 hsp Htå – Ro. Maskinelle arbejder på rammeaftale | M1: Mængde Stadie 6 – Afsluttende manuelle arbejder | N1: Mængde Stadie 7 - 3. og 4. hovedspor Høje Taastrup – Roskilde spærret. Manuelle arbejder | O1: Mængde Stadie 7a - 2. hovedspor Høje Taastrup – Roskilde spærret | P1: Mængde Stadie 8 – 3 + 4 hovedspor Htå – Ro Maskinelle arbejder på rammeaftale | Q1: Mængde Stadie 9 - 3. og 4. hovedspor Høje Taastrup – Roskilde spærret. Afsluttende manuelle arbejder | R1: Mængde i alt | S1: Enhedspris DKK | T1: I alt DKK
A2: 10 | B2: Sikring | T2: =R2*S2 -> 0
A3: 10.1 | B3: Kabeldåser og fordelingshuse | T3: =R3*S3 -> 0
A4: 10.1.1 | B4: Demontage af kabeldåse | C4: STK | D4: 0 | E4: 2 | F4: 0 | G4: 0 | H4: 0 | I4: 24 | J4: 0 | K4: 0 | L4: 0 | M4: 0 | N4: 0 | O4: 0 | P4: 0 | Q4: 0 | R4: =SUM(D4:Q4) -> 26 | S4: 5948 | T4: =R4*S4 -> 154648
A5: 10.1.2 | B5: Montering af kabeldåse for sporisolation | C5: STK | D5: 0 | E5: 2 | F5: 0 | G5: 0 | H5: 0 | I5: 24 | J5: 0 | K5: 0 | L5: 0 | M5: 0 | N5: 0 | O5: 0 | P5: 0 | Q5: 0 | R5: =SUM(D5:Q5) -> 26 | S5: 9424 | T5: =R5*S5 -> 245024
A6: 10.1.7 | B6: Afprøvning af sporisolation | C6: STK | D6: 0 | E6: 18 | F6: 0 | G6: 0 | H6: 0 | I6: 26 | J6: 0 | K6: 0 | L6: 0 | M6: 0 | N6: 0 | O6: 0 | P6: 0 | Q6: 0 | R6: =SUM(D6:Q6) -> 44 | S6: 5978 | T6: =R6*S6 -> 263032
A7: 10.4 | B7: ATC/ATP | T7: =R7*S7 -> 0
A8: 10.4.1 | B8: Demontering af ATC-balise | C8: STK | D8: 0 | E8: 2 | F8: 0 | G8: 0 | H8: 0 | I8: 2 | J8: 0 | K8: 0 | L8: 0 | M8: 0 | N8: 0 | O8: 0 | P8: 0 | Q8: 0 | R8: =SUM(D8:Q8) -> 4 | S8: 3021 | T8: =R8*S8 -> 12084
A9: 10.4.2 | B9: Montering af ATC-balise | C9: STK | D9: 0 | E9: 2 | F9: 0 | G9: 0 | H9: 0 | I9: 2 | J9: 0 | K9: 0 | L9: 0 | M9: 0 | N9: 0 | O9: 0 | P9: 0 | Q9: 0 | R9: =SUM(D9:Q9) -> 4 | S9: 2955 | T9: =R9*S9 -> 11820
A10: 10.4.5 | B10: Demontering af sideforlagt linjeleder | C10: M | D10: 0 | E10: 0 | F10: 0 | G10: 0 | H10: 0 | I10: 12000 | J10: 0 | K10: 0 | L10: 0 | M10: 0 | N10: 0 | O10: 0 | P10: 0 | Q10: 0 | R10: =SUM(D10:Q10) -> 12000 | S10: 52 | T10: =R10*S10 -> 624000
A11: 10.4.6 | B11: Montering af sideforlagt linjeleder | C11: M | D11: 0 | E11: 0 | F11: 0 | G11: 0 | H11: 0 | I11: 12000 | J11: 0 | K11: 0 | L11: 0 | M11: 0 | N11: 0 | O11: 0 | P11: 0 | Q11: 0 | R11: =SUM(D11:Q11) -> 12000 | S11: 73 | T11: =R11*S11 -> 876000
A12: 10.4.7 | B12: Afprøvning af ATC balise | C12: STK | D12: 0 | E12: 2 | F12: 0 | G12: 0 | H12: 0 | I12: 2 | J12: 0 | K12: 0 | L12: 0 | M12: 0 | N12: 0 | O12: 0 | P12: 0 | Q12: 0 | R12: =SUM(D12:Q12) -> 4 | S12: 4167 | T12: =R12*S12 -> 16668
A13: 10.4.9 | B13: Afprøvning af sideforlagt linjeleder | C13: STK | D13: 0 | E13: 24 | F13: 0 | G13: 11 | H13: 0 | I13: 17 | J13: 0 | K13: 0 | L13: 0 | M13: 0 | N13: 0 | O13: 0 | P13: 0 | Q13: 0 | R13: =SUM(D13:Q13) -> 52 | S13: 1528 | T13: =R13*S13 -> 79456
A14: 10.8 | B14: Kabler og ledninger | T14: =R14*S14 -> 0
A15: 10.8.7 | B15: Demontering af tværforbinder | C15: STK | D15: 0 | E15: 2 | F15: 0 | G15: 0 | H15: 0 | I15: 1 | J15: 0 | K15: 0 | L15: 0 | M15: 0 | N15: 0 | O15: 0 | P15: 0 | Q15: 0 | R15: =SUM(D15:Q15) -> 3 | S15: 1423 | T15: =R15*S15 -> 4269
A16: 10.8.8 | B16: Montering af tværforbinder | C16: STK | D16: 0 | E16: 2 | F16: 0 | G16: 0 | H16: 0 | I16: 1 | J16: 0 | K16: 0 | L16: 0 | M16: 0 | N16: 0 | O16: 0 | P16: 0 | Q16: 0 | R16: =SUM(D16:Q16) -> 3 | S16: 1897 | T16: =R16*S16 -> 5691
A17: 10.10 | B17: Sikringsarbejder i forbindelse med slutjustering | T17: =R17*S17 -> 0
A18: 10.10.1 | B18: De- og genmontering af skinnetilledninger fra kabeldåse | C18: STK | D18: 0 | E18: 2 | F18: 0 | G18: 0 | H18: 0 | I18: 1 | J18: 0 | K18: 0 | L18: 0 | M18: 0 | N18: 0 | O18: 0 | P18: 0 | Q18: 0 | R18: =SUM(D18:Q18) -> 3 | S18: 5986 | T18: =R18*S18 -> 17958
A19: 10.10.2 | B19: De- og genmontering af ATC/ATP baliser | C19: STK | D19: 0 | E19: 2 | F19: 0 | G19: 0 | H19: 0 | I19: 2 | J19: 0 | K19: 0 | L19: 0 | M19: 0 | N19: 0 | O19: 0 | P19: 0 | Q19: 0 | R19: =SUM(D19:Q19) -> 4 | S19: 5024 | T19: =R19*S19 -> 20096
A20: 10.10.4 | B20: De- og genmontering af tværforbinder | C20: STK | D20: 0 | E20: 2 | F20: 0 | G20: 0 | H20: 0 | I20: 1 | J20: 0 | K20: 0 | L20: 0 | M20: 0 | N20: 0 | O20: 0 | P20: 0 | Q20: 0 | R20: =SUM(D20:Q20) -> 3 | S20: 1840 | T20: =R20*S20 -> 5520
A21: 10.X | B21: Projektspecifikke arbejder ifm. Sikring | T21: =R21*S21 -> 0
A22: 10.X.1 | B22: Klipning og demontering af sideforlagt linjeleder | C22: STK | D22: 0 | E22: 24 | F22: 0 | G22: 11 | H22: 0 | I22: 10 | J22: 0 | K22: 0 | L22: 0 | M22: 0 | N22: 0 | O22: 0 | P22: 0 | Q22: 0 | R22: =SUM(D22:Q22) -> 45 | S22: 6080 | T22: =R22*S22 -> 273600
A23: 10.X.2 | B23: Splidsning og montering af sideforlagt linjeleder | C23: STK | D23: 0 | E23: 24 | F23: 0 | G23: 11 | H23: 0 | I23: 10 | J23: 0 | K23: 0 | L23: 0 | M23: 0 | N23: 0 | O23: 0 | P23: 0 | Q23: 0 | R23: =SUM(D23:Q23) -> 45 | S23: 10306 | T23: =R23*S23 -> 463770
A24: 10.X.3 | B24: Slutjustering | C24: STK | T24: =R24*S24 -> 0
A25: 10.X.3.1 | B25: Slutjustering - Klipning af sideforlagt linjeleder | C25: STK | D25: 0 | E25: 24 | F25: 0 | G25: 11 | H25: 0 | I25: 10 | J25: 0 | K25: 0 | L25: 0 | M25: 0 | N25: 0 | O25: 0 | P25: 0 | Q25: 0 | R25: =SUM(D25:Q25) -> 45 | S25: 6251 | T25: =R25*S25 -> 281295
A26: 10.X.3.2 | B26: Slutjustering - Splidsning af sideforlagt linjeleder | C26: STK | D26: 0 | E26: 24 | F26: 0 | G26: 11 | H26: 0 | I26: 10 | J26: 0 | K26: 0 | L26: 0 | M26: 0 | N26: 0 | O26: 0 | P26: 0 | Q26: 0 | R26: =SUM(D26:Q26) -> 45 | S26: 10613 | T26: =R26*S26 -> 477585
A27: 10.X.4 | B27: Fejlretning efter ibrugtagning | C27: STK | D27: 0 | E27: 1 | F27: 0 | G27: 1 | H27: 0 | I27: 1 | J27: 0 | K27: 0 | L27: 0 | M27: 0 | N27: 0 | O27: 0 | P27: 0 | Q27: 0 | R27: =SUM(D27:Q27) -> 3 | S27: 27237 | T27: =R27*S27 -> 81711
A28: 10.X.5 | B28: Fejlretning under udførelse | C28: T | T28: =R28*S28 -> 0
A29: 10.X.5.1 | B29: Rådighedsvagt | C29: T | D29: 0 | E29: 248 | F29: 0 | G29: 336 | H29: 0 | I29: 1160 | J29: 0 | K29: 0 | L29: 0 | M29: 0 | N29: 0 | O29: 0 | P29: 0 | Q29: 0 | R29: =SUM(D29:Q29) -> 1744 | S29: 1477 | T29: =R29*S29 -> 2575888
A30: 10.X.5.2 | B30: Fejlretning | C30: T | D30: 0 | E30: 20 | F30: 0 | G30: 20 | H30: 0 | I30: 60 | J30: 0 | K30: 0 | L30: 0 | M30: 0 | N30: 0 | O30: 0 | P30: 0 | Q30: 0 | R30: =SUM(D30:Q30) -> 100 | S30: 2068 | T30: =R30*S30 -> 206800
A31: 10.X.6 | B31: Klipning og demontering af sideforlagt linjeleder | C31: STK | T31: =R31*S31 -> 0
B33: Samlet tilbudssum ekskl. moms (i DKK) | T33: =SUM(T2:T31) -> 6696915
B34: Overføres til "Hovedtilbudsliste"

Sheet 12 Broer og konstruktioner
A1: Fagpost (FP) Hovedpost (HP) Post (P) Underpost (UP) | B1: Broer og konstruktioner | C1: Enhed | D1: Mængde Forberedende arbejder | E1: Mængde Stadie 1 -1.+ 2. hovedspor Htå -Ro spærret | F1: Mængde Stadie 1a | G1: Mængde Stadie 3 – 3. + 4. hovedspor Htå - Ro spærret | H1: Mængde Stadie 3a | I1: Mængde Stadie 2 – 2. + 3. hovedspor Htå – Ro spærret | J1: Mængde Stadie 2a | K1: Mængde Stadie 4 – 1. og 2. hovedspor Høje Taastrup – Roskilde spærret | L1: Mængde Stadie 5 – 1 + 2 hsp Htå – Ro. Maskinelle arbejder på rammeaftale | M1: Mængde Stadie 6 – Afsluttende manuelle arbejder | N1: Mængde Stadie 7 - 3. og 4. hovedspor Høje Taastrup – Roskilde spærret. Manuelle arbejder | O1: Mængde Stadie 7a - 2. hovedspor Høje Taastrup – Roskilde spærret | P1: Mængde Stadie 8 – 3 + 4 hovedspor Htå – Ro Maskinelle arbejder på rammeaftale | Q1: Mængde Stadie 9 - 3. og 4. hovedspor Høje Taastrup – Roskilde spærret. Afsluttende manuelle arbejder | R1: Mængde i alt | S1: Enhedspris DKK | T1: I alt DKK
A2: 12 | B2: Broer og konstruktioner | T2: =R2*S2 -> 0
A3: 12.1 | B3: Forberedende arbejder | T3: =R3*S3 -> 0
A4: 12.1.1 | B4: Rydning | C4: SUM | D4: 0 | E4: 1 | F4: 0 | G4: 1 | H4: 0 | I4: 0 | J4: 0 | K4: 0 | L4: 0 | M4: 0 | N4: 0 | O4: 0 | P4: 0 | Q4: 0 | R4: =SUM(D4:Q4) -> 2 | S4: 33461 | T4: =R4*S4 -> 66922
A5: 12.2 | B5: Betonelementer | T5: =R5*S5 -> 0
A6: 12.2.3 | B6: Fremstilling, transport og montering af kantbjælkeelementer inklusiv sammenstøbning og fastgørelse | C6: M | D6: 0 | E6: 30 | F6: 0 | G6: 43 | H6: 0 | I6: 0 | J6: 0 | K6: 0 | L6: 0 | M6: 0 | N6: 0 | O6: 0 | P6: 0 | Q6: 0 | R6: =SUM(D6:Q6) -> 73 | S6: 9899 | T6: =R6*S6 -> 722627
A7: 12.10 | B7: Autoværn og tilhørende udstyr | T7: =R7*S7 -> 0
A8: 12.10.1 | B8: Nedtagning og bortskaffelse af rækværk | T8: =R8*S8 -> 0
A9: 12.10.1.1 | B9: Nedtagning og bortskaffelse af eksisterende rækværk | C9: M | D9: 0 | E9: 61 | F9: 0 | G9: 22 | H9: 0 | I9: 0 | J9: 0 | K9: 0 | L9: 0 | M9: 0 | N9: 0 | O9: 0 | P9: 0 | Q9: 0 | R9: =SUM(D9:Q9) -> 83 | S9: 1789 | T9: =R9*S9 -> 148487
A10: 12.10.1.2 | B10: Levering, montering og demontage af midlertidigt rækværk | C10: M | D10: 0 | E10: 61 | F10: 0 | G10: 10 | H10: 0 | I10: 0 | J10: 0 | K10: 0 | L10: 0 | M10: 0 | N10: 0 | O10: 0 | P10: 0 | Q10: 0 | R10: =SUM(D10:Q10) -> 71 | S10: 1697 | T10: =R10*S10 -> 120487
A11: 12.10.1.3 | B11: Behugning og reparation af beton, inklusiv skæring og overfladebehandling af eksisterende rækværk. | C11: M | D11: 0 | E11: 61 | F11: 0 | G11: 22 | H11: 0 | I11: 0 | J11: 0 | K11: 0 | L11: 0 | M11: 0 | N11: 0 | O11: 0 | P11: 0 | Q11: 0 | R11: =SUM(D11:Q11) -> 83 | S11: 376 | T11: =R11*S11 -> 31208
A12: 12.10.3 | B12: Rækværk | C12: M | D12: 0 | E12: 0 | F12: 0 | G12: 0 | H12: 0 | I12: 0 | J12: 0 | K12: 0 | L12: 0 | M12: 0 | N12: 0 | O12: 0 | P12: 0 | Q12: 0 | R12: =SUM(D12:Q12) -> 0 | T12: =R12*S12 -> 0
A13: 12.10.3.1 | B13: Levering og montering af rækværk på overside konstruktion | C13: M | D13: 0 | E13: 28 | F13: 0 | G13: 0 | H13: 0 | I13: 0 | J13: 0 | K13: 0 | L13: 0 | M13: 0 | N13: 0 | O13: 0 | P13: 0 | Q13: 0 | R13: =SUM(D13:Q13) -> 28 | S13: 5045 | T13: =R13*S13 -> 141260
A14: 12.10.3.2 | B14: Levering og montering af rækværk på yderside konstruktion | C14: M | D14: 0 | E14: 30 | F14: 0 | G14: 10 | H14: 0 | I14: 0 | J14: 0 | K14: 0 | L14: 0 | M14: 0 | N14: 0 | O14: 0 | P14: 0 | Q14: 0 | R14: =SUM(D14:Q14) -> 40 | S14: 5222 | T14: =R14*S14 -> 208880
A15: 12.10.3.3 | B15: Levering og montering af gangbro med rækværk | C15: M | D15: 0 | E15: 3 | F15: 0 | G15: 4 | H15: 0 | I15: 0 | J15: 0 | K15: 0 | L15: 0 | M15: 0 | N15: 0 | O15: 0 | P15: 0 | Q15: 0 | R15: =SUM(D15:Q15) -> 7 | S15: 43403 | T15: =R15*S15 -> 303821
A16: 12.10.3.4 | B16: Levering og montering af rørrækværk på skråninger, inklusiv fundamenter. | C16: M | D16: 0 | E16: 13 | F16: 0 | G16: 0 | H16: 0 | I16: 0 | J16: 0 | K16: 0 | L16: 0 | M16: 0 | N16: 0 | O16: 0 | P16: 0 | Q16: 0 | R16: =SUM(D16:Q16) -> 13 | S16: 7180 | T16: =R16*S16 -> 93340
A17: 12.10.3.5 | B17: Levering og montering af ballastskærm på rækværk. | C17: M | D17: 0 | E17: 21 | F17: 0 | G17: 0 | H17: 0 | I17: 0 | J17: 0 | K17: 0 | L17: 0 | M17: 0 | N17: 0 | O17: 0 | P17: 0 | Q17: 0 | R17: =SUM(D17:Q17) -> 21 | S17: 2026 | T17: =R17*S17 -> 42546
A18: 12.10.a | B18: Kabelstiger | C18: M | D18: 0 | E18: 0 | F18: 0 | G18: 50 | H18: 0 | I18: 0 | J18: 0 | K18: 0 | L18: 0 | M18: 0 | N18: 0 | O18: 0 | P18: 0 | Q18: 0 | R18: =SUM(D18:Q18) -> 50 | S18: 2647 | T18: =R18*S18 -> 132350
A19: 12.10.b | B19: Ballastfang | C19: STK | D19: 0 | E19: 6 | F19: 0 | G19: 9 | H19: 0 | I19: 0 | J19: 0 | K19: 0 | L19: 0 | M19: 0 | N19: 0 | O19: 0 | P19: 0 | Q19: 0 | R19: =SUM(D19:Q19) -> 15 | S19: 5463 | T19: =R19*S19 -> 81945
A20: 12.11 | B20: Fundering | T20: =R20*S20 -> 0
A21: 12.11.1 | B21: Anstilling for nedbringning af pæle | C21: SUM | D21: 0 | E21: 1 | F21: 0 | G21: 1 | H21: 0 | I21: 0 | J21: 0 | K21: 0 | L21: 0 | M21: 0 | N21: 0 | O21: 0 | P21: 0 | Q21: 0 | R21: =SUM(D21:Q21) -> 2 | S21: 21255 | T21: =R21*S21 -> 42510
A22: 12.X | B22: Projektspecifikke arbejder ifm. Broer og konstruktioner | T22: =R22*S22 -> 0
A23: 12.X.1 | B23: Ballastplade | C23: M | D23: 0 | E23: 16 | F23: 0 | G23: 0 | H23: 0 | I23: 0 | J23: 0 | K23: 0 | L23: 0 | M23: 0 | N23: 0 | O23: 0 | P23: 0 | Q23: 0 | R23: =SUM(D23:Q23) -> 16 | S23: 3456 | T23: =R23*S23 -> 55296
A24: 12.X.2 | B24: Skruefundamenter | C24: STK | D24: 0 | E24: 8 | F24: 0 | G24: 16 | H24: 0 | I24: 0 | J24: 0 | K24: 0 | L24: 0 | M24: 0 | N24: 0 | O24: 0 | P24: 0 | Q24: 0 | R24: =SUM(D24:Q24) -> 24 | S24: 7398 | T24: =R24*S24 -> 177552
B26: Samlet tilbudssum ekskl. moms (i DKK) | T26: =SUM(T2:T24) -> 2369231
B27: Overføres til "Hovedtilbudsliste"

Sheet 14 Håndtering og bortskaffelse
A1: Fagpost (FP) Hovedpost (HP) Post (P) Underpost (UP) | B1: Håndtering og bortskaffelse | C1: Enhed | D1: Mængde Forberedende arbejder | E1: Mængde Stadie 1 -1.+ 2. hovedspor Htå -Ro spærret | F1: Mængde Stadie 1a | G1: Mængde Stadie 3 – 3. + 4. hovedspor Htå - Ro spærret | H1: Mængde Stadie 3a | I1: Mængde Stadie 2 – 2. + 3. hovedspor Htå – Ro spærret | J1: Mængde Stadie 2a | K1: Mængde Stadie 4 – 1. og 2. hovedspor Høje Taastrup – Roskilde spærret | L1: Mængde Stadie 5 – 1 + 2 hsp Htå – Ro. Maskinelle arbejder på rammeaftale | M1: Mængde Stadie 6 – Afsluttende manuelle arbejder | N1: Mængde Stadie 7 - 3. og 4. hovedspor Høje Taastrup – Roskilde spærret. Manuelle arbejder | O1: Mængde Stadie 7a - 2. hovedspor Høje Taastrup – Roskilde spærret | P1: Mængde Stadie 8 – 3 + 4 hovedspor Htå – Ro Maskinelle arbejder på rammeaftale | Q1: Mængde Stadie 9 - 3. og 4. hovedspor Høje Taastrup – Roskilde spærret. Afsluttende manuelle arbejder | R1: Mængde i alt | S1: Enhedspris DKK | T1: I alt DKK
A2: 14 | B2: Håndtering og bortskaffelse | T2: =R2*S2 -> 0
A3: 14.1 | B3: Håndtering og bortskaffelse af Restprodukter | T3: =R3*S3 -> 0
A4: 14.1.1 | B4: Bortskaffelse af Restprodukter omfattende skærver, bagharp, jord- og grusmaterialer (Sjælland uden kartering på Banedanmarks udpegede arbejdspladser) | T4: =R4*S4 -> 0
A5: 14.1.1.1 | B5: Skærver | C5: M3 | D5: 5 | E5: 42 | F5: 0 | G5: 0 | H5: 0 | I5: 1562 | J5: 0 | K5: 0 | L5: 0 | M5: 0 | N5: 0 | O5: 0 | P5: 0 | Q5: 0 | R5: =SUM(D5:Q5) -> 1609 | S5: 80 | T5: =R5*S5 -> 128720
A6: 14.1.1.a | B6: Bagharp kl. 0/1 | C6: M3 | D6: 4 | E6: 29 | F6: 0 | G6: 0 | H6: 0 | I6: 1093 | J6: 0 | K6: 0 | L6: 0 | M6: 0 | N6: 0 | O6: 0 | P6: 0 | Q6: 0 | R6: =SUM(D6:Q6) -> 1126 | S6: 615 | T6: =R6*S6 -> 692490
A7: 14.1.1.b | B7: Bagharp kl. 2/3 | C7: M3 | D7: 1 | E7: 13 | F7: 0 | G7: 0 | H7: 0 | I7: 469 | J7: 0 | K7: 0 | L7: 0 | M7: 0 | N7: 0 | O7: 0 | P7: 0 | Q7: 0 | R7: =SUM(D7:Q7) -> 483 | S7: 753 | T7: =R7*S7 -> 363699
A8: 14.1.1.c | B8: Jord kl. 0/1 | C8: M3 | D8: 30 | E8: 237 | F8: 0 | G8: 0 | H8: 0 | I8: 9332 | J8: 0 | K8: 0 | L8: 0 | M8: 0 | N8: 0 | O8: 0 | P8: 0 | Q8: 0 | R8: =SUM(D8:Q8) -> 9599 | S8: 615 | T8: =R8*S8 -> 5903385
A9: 14.1.1.d | B9: Jord kl. 2/3 | C9: M3 | D9: 13 | E9: 102 | F9: 0 | G9: 0 | H9: 0 | I9: 3485 | J9: 0 | K9: 0 | L9: 0 | M9: 0 | N9: 0 | O9: 0 | P9: 0 | Q9: 0 | R9: =SUM(D9:Q9) -> 3600 | S9: 753 | T9: =R9*S9 -> 2710800
A10: 14.1.1.e | B10: Grusmaterialer (underballast) kl. 0/1 | C10: M3 | D10: 0 | E10: 37 | F10: 0 | G10: 0 | H10: 0 | I10: 10 | J10: 0 | K10: 0 | L10: 0 | M10: 0 | N10: 0 | O10: 0 | P10: 0 | Q10: 0 | R10: =SUM(D10:Q10) -> 47 | S10: 615 | T10: =R10*S10 -> 28905
A11: 14.1.1.f | B11: Grusmaterialer (underballast) kl. 2/3 | C11: M3 | D11: 0 | E11: 16 | F11: 0 | G11: 0 | H11: 0 | I11: 4 | J11: 0 | K11: 0 | L11: 0 | M11: 0 | N11: 0 | O11: 0 | P11: 0 | Q11: 0 | R11: =SUM(D11:Q11) -> 20 | S11: 753 | T11: =R11*S11 -> 15060
A12: 14.1.5 | B12: Bortskaffelse af restprodukter omfattende betonaffald | C12: TON | D12: 0 | E12: 1 | F12: 0 | G12: 0 | H12: 0 | I12: 1 | J12: 0 | K12: 0 | L12: 0 | M12: 0 | N12: 0 | O12: 0 | P12: 0 | Q12: 0 | R12: =SUM(D12:Q12) -> 2 | S12: 49 | T12: =R12*S12 -> 98
A13: 14.1.a | B13: Bortskaffelse af plastik | C13: TON | D13: 0 | E13: 1 | F13: 0 | G13: 1 | H13: 0 | I13: 40 | J13: 0 | K13: 2 | L13: 0 | M13: 0 | N13: 2 | O13: 0 | P13: 0 | Q13: 0 | R13: =SUM(D13:Q13) -> 46 | S13: 2760 | T13: =R13*S13 -> 126960
A14: 14.1.b | B14: Bortskaffelse af røgkammermuld | C14: M3 | D14: 0 | E14: 3 | F14: 0 | G14: 0 | H14: 0 | I14: 0 | J14: 0 | K14: 0 | L14: 0 | M14: 0 | N14: 0 | O14: 0 | P14: 0 | Q14: 0 | R14: =SUM(D14:Q14) -> 3 | S14: 539 | T14: =R14*S14 -> 1617
A15: 14.1.c | B15: Bortskaffelse af rækværk | C15: M | D15: 0 | E15: 61 | F15: 0 | G15: 22 | H15: 0 | I15: 0 | J15: 0 | K15: 0 | L15: 0 | M15: 0 | N15: 0 | O15: 0 | P15: 0 | Q15: 0 | R15: =SUM(D15:Q15) -> 83 | S15: 28 | T15: =R15*S15 -> 2324
A16: 14.1.d | B16: Bortskaffelse af SF-sten | C16: TON | D16: 0 | E16: 4 | F16: 0 | G16: 0 | H16: 0 | I16: 0 | J16: 0 | K16: 0 | L16: 0 | M16: 0 | N16: 0 | O16: 0 | P16: 0 | Q16: 0 | R16: =SUM(D16:Q16) -> 4 | S16: 49 | T16: =R16*S16 -> 196
A17: 14.1.e | B17: Bortskaffelse af skinnestolper | C17: TON | D17: 0 | E17: 1 | F17: 0 | G17: 0 | H17: 0 | I17: 0 | J17: 0 | K17: 0 | L17: 0 | M17: 0 | N17: 0 | O17: 0 | P17: 0 | Q17: 0 | R17: =SUM(D17:Q17) -> 1 | S17: 49 | T17: =R17*S17 -> 49
B19: Samlet tilbudssum ekskl. moms (i DKK) | T19: =SUM(T2:T17) -> 9974303
B20: Overføres til "Hovedtilbudsliste"

Sheet 15 Administration og arbejdspla
A1: Fagpost (FP) Hovedpost (HP) Post (P) Underpost (UP) | B1: Administration og arbejdsplads | C1: Enhed | D1: Mængde Forberedende arbejder | E1: Mængde Stadie 1 -1.+ 2. hovedspor Htå -Ro spærret | F1: Mængde Stadie 1a | G1: Mængde Stadie 3 – 3. + 4. hovedspor Htå - Ro spærret | H1: Mængde Stadie 3a | I1: Mængde Stadie 2 – 2. + 3. hovedspor Htå – Ro spærret | J1: Mængde Stadie 2a | K1: Mængde Stadie 4 – 1. og 2. hovedspor Høje Taastrup – Roskilde spærret | L1: Mængde Stadie 5 – 1 + 2 hsp Htå – Ro. Maskinelle arbejder på rammeaftale | M1: Mængde Stadie 6 – Afsluttende manuelle arbejder | N1: Mængde Stadie 7 - 3. og 4. hovedspor Høje Taastrup – Roskilde spærret. Manuelle arbejder | O1: Mængde Stadie 7a - 2. hovedspor Høje Taastrup – Roskilde spærret | P1: Mængde Stadie 8 – 3 + 4 hovedspor Htå – Ro Maskinelle arbejder på rammeaftale | Q1: Mængde Stadie 9 - 3. og 4. hovedspor Høje Taastrup – Roskilde spærret. Afsluttende manuelle arbejder | R1: Mængde i alt | S1: Enhedspris DKK | T1: I alt DKK
A2: 15 | B2: Administration og arbejdsplads | T2: =R2*S2 -> 0
A3: 15.1 | B3: Mobiliseringsperioden | T3: =R3*S3 -> 0
A4: 15.1.1 | B4: Administration i mobiliseringsperioden | C4: SUM | D4: 1 | E4: 0 | F4: 0 | G4: 0 | H4: 0 | I4: 0 | J4: 0 | K4: 0 | L4: 0 | M4: 0 | N4: 0 | O4: 0 | P4: 0 | Q4: 0 | R4: =SUM(D4:Q4) -> 1 | S4: 3983069 | T4: =R4*S4 -> 3983069
A5: 15.1.2 | B5: Kontrol af fikspunkter | C5: SUM | D5: 1 | E5: 0 | F5: 0 | G5: 0 | H5: 0 | I5: 0 | J5: 0 | K5: 0 | L5: 0 | M5: 0 | N5: 0 | O5: 0 | P5: 0 | Q5: 0 | R5: =SUM(D5:Q5) -> 1 | S5: 60794 | T5: =R5*S5 -> 60794
A6: 15.2 | B6: Arbejdsområder og arbejdspladser | T6: =R6*S6 -> 0
A7: 15.2.1 | B7: Arbejdspladser og adgangsveje | C7: SUM | D7: 0 | E7: 0 | F7: 0 | G7: 0 | H7: 0 | I7: 0 | J7: 0 | K7: 0 | L7: 0 | M7: 0 | N7: 0 | O7: 0 | P7: 0 | Q7: 0 | R7: =SUM(D7:Q7) -> 0 | T7: =R7*S7 -> 0
A8: 15.2.1.1 | B8: Grus til sikring af kørefasthed | C8: M3 | D8: 22250 | E8: 0 | F8: 0 | G8: 0 | H8: 0 | I8: 0 | J8: 0 | K8: 0 | L8: 0 | M8: 0 | N8: 0 | O8: 0 | P8: 0 | Q8: 0 | R8: =SUM(D8:Q8) -> 22250 | S8: 626 | T8: =R8*S8 -> 13928500
A9: 15.2.1.2 | B9: Jernplader til sikring af kørefasthed | C9: M2 | D9: 5500 | E9: 0 | F9: 0 | G9: 0 | H9: 0 | I9: 0 | J9: 0 | K9: 0 | L9: 0 | M9: 0 | N9: 0 | O9: 0 | P9: 0 | Q9: 0 | R9: =SUM(D9:Q9) -> 5500 | S9: 152 | T9: =R9*S9 -> 836000
A10: 15.2.1.a | B10: Depot 1 | C10: SUM | D10: 1 | E10: 0 | F10: 0 | G10: 0 | H10: 0 | I10: 0 | J10: 0 | K10: 0 | L10: 0 | M10: 0 | N10: 0 | O10: 0 | P10: 0 | Q10: 0 | R10: =SUM(D10:Q10) -> 1 | S10: 888505 | T10: =R10*S10 -> 888505
A11: 15.2.1.b | B11: Depot 2 | C11: SUM | D11: 1 | E11: 0 | F11: 0 | G11: 0 | H11: 0 | I11: 0 | J11: 0 | K11: 0 | L11: 0 | M11: 0 | N11: 0 | O11: 0 | P11: 0 | Q11: 0 | R11: =SUM(D11:Q11) -> 1 | S11: 390363 | T11: =R11*S11 -> 390363
A12: 15.2.1.c | B12: Depot 3 | C12: SUM | D12: 1 | E12: 0 | F12: 0 | G12: 0 | H12: 0 | I12: 0 | J12: 0 | K12: 0 | L12: 0 | M12: 0 | N12: 0 | O12: 0 | P12: 0 | Q12: 0 | R12: =SUM(D12:Q12) -> 1 | S12: 987493 | T12: =R12*S12 -> 987493
A13: 15.2.1.d | B13: Depot 4 | C13: SUM | D13: 1 | E13: 0 | F13: 0 | G13: 0 | H13: 0 | I13: 0 | J13: 0 | K13: 0 | L13: 0 | M13: 0 | N13: 0 | O13: 0 | P13: 0 | Q13: 0 | R13: =SUM(D13:Q13) -> 1 | S13: 934568 | T13: =R13*S13 -> 934568
A14: 15.2.1.e | B14: Arbejdsareal 4a | C14: SUM | D14: 1 | E14: 0 | F14: 0 | G14: 0 | H14: 0 | I14: 0 | J14: 0 | K14: 0 | L14: 0 | M14: 0 | N14: 0 | O14: 0 | P14: 0 | Q14: 0 | R14: =SUM(D14:Q14) -> 1 | S14: 54803 | T14: =R14*S14 -> 54803
A15: 15.2.1.f | B15: Arbejdsareal 4b | C15: SUM | D15: 1 | E15: 0 | F15: 0 | G15: 0 | H15: 0 | I15: 0 | J15: 0 | K15: 0 | L15: 0 | M15: 0 | N15: 0 | O15: 0 | P15: 0 | Q15: 0 | R15: =SUM(D15:Q15) -> 1 | S15: 53217 | T15: =R15*S15 -> 53217
A16: 15.2.1.g | B16: Depot 5 | C16: SUM | D16: 1 | E16: 0 | F16: 0 | G16: 0 | H16: 0 | I16: 0 | J16: 0 | K16: 0 | L16: 0 | M16: 0 | N16: 0 | O16: 0 | P16: 0 | Q16: 0 | R16: =SUM(D16:Q16) -> 1 | S16: 651267 | T16: =R16*S16 -> 651267
A17: 15.2.1.h | B17: Arbejdsareal 5a | C17: SUM | D17: 1 | E17: 0 | F17: 0 | G17: 0 | H17: 0 | I17: 0 | J17: 0 | K17: 0 | L17: 0 | M17: 0 | N17: 0 | O17: 0 | P17: 0 | Q17: 0 | R17: =SUM(D17:Q17) -> 1 | S17: 54803 | T17: =R17*S17 -> 54803
A18: 15.2.1.i | B18: Arbejdsareal 5b | C18: SUM | D18: 1 | E18: 0 | F18: 0 | G18: 0 | H18: 0 | I18: 0 | J18: 0 | K18: 0 | L18: 0 | M18: 0 | N18: 0 | O18: 0 | P18: 0 | Q18: 0 | R18: =SUM(D18:Q18) -> 1 | S18: 54803 | T18: =R18*S18 -> 54803
A19: 15.2.1.j | B19: Depot 6 | C19: SUM | D19: 1 | E19: 0 | F19: 0 | G19: 0 | H19: 0 | I19: 0 | J19: 0 | K19: 0 | L19: 0 | M19: 0 | N19: 0 | O19: 0 | P19: 0 | Q19: 0 | R19: =SUM(D19:Q19) -> 1 | S19: 486936 | T19: =R19*S19 -> 486936
... A36: 15.2.4 | B36: Vinterforanstaltning | C36: SUM | D36: 1 | E36: 0 | F36: 0 | G36: 0 | H36: 0 | I36: 0 | J36: 0 | K36: 0 | L36: 0 | M36: 0 | N36: 0 | O36: 0 | P36: 0 | Q36: 0 | R36: =SUM(D36:Q36) -> 1 | S36: 109140 | T36: =R36*S36 -> 109140
A37: 15.3 | B37: Administration | T37: =R37*S37 -> 0
A38: 15.3.1 | B38: Administration | C38: SUM | D38: 1 | E38: 0 | F38: 0 | G38: 0 | H38: 0 | I38: 0 | J38: 0 | K38: 0 | L38: 0 | M38: 0 | N38: 0 | O38: 0 | P38: 0 | Q38: 0 | R38: =SUM(D38:Q38) -> 1 | S38: 8765120 | T38: =R38*S38 -> 8765120
A39: 15.4 | B39: Jernbanesikkerhed | T39: =R39*S39 -> 0
A40: 15.4.1 | B40: Jernbanesikkerhed | C40: SUM | D40: 1 | E40: 0 | F40: 0 | G40: 0 | H40: 0 | I40: 0 | J40: 0 | K40: 0 | L40: 0 | M40: 0 | N40: 0 | O40: 0 | P40: 0 | Q40: 0 | R40: =SUM(D40:Q40) -> 1 | S40: 8746692 | T40: =R40*S40 -> 8746692
A41: 15.5 | B41: Arbejdsmiljøkoordinering | T41: =R41*S41 -> 0
B43: Samlet tilbudssum ekskl. moms (i DKK) | T43: =SUM(T2:T41) -> 48827255
B44: Overføres til "Hovedtilbudsliste"

Sheet 16 Ændringsydelser
A1: Fagpost (FP) Hovedpost (HP) Post (P) Underpost (UP) | B1: Ændringsydelser | C1: Enhed | D1: Mængde Forberedende arbejder | E1: Mængde Stadie 1 -1.+ 2. hovedspor Htå -Ro spærret | F1: Mængde Stadie 1a | G1: Mængde Stadie 3 – 3. + 4. hovedspor Htå - Ro spærret | H1: Mængde Stadie 3a | I1: Mængde Stadie 2 – 2. + 3. hovedspor Htå – Ro spærret | J1: Mængde Stadie 2a | K1: Mængde Stadie 4 – 1. og 2. hovedspor Høje Taastrup – Roskilde spærret | L1: Mængde Stadie 5 – 1 + 2 hsp Htå – Ro. Maskinelle arbejder på rammeaftale | M1: Mængde Stadie 6 – Afsluttende manuelle arbejder | N1: Mængde Stadie 7 - 3. og 4. hovedspor Høje Taastrup – Roskilde spærret. Manuelle arbejder | O1: Mængde Stadie 7a - 2. hovedspor Høje Taastrup – Roskilde spærret | P1: Mængde Stadie 8 – 3 + 4 hovedspor Htå – Ro Maskinelle arbejder på rammeaftale | Q1: Mængde Stadie 9 - 3. og 4. hovedspor Høje Taastrup – Roskilde spærret. Afsluttende manuelle arbejder | R1: Mængde i alt | S1: Enhedspris DKK | T1: I alt DKK
A2: 16 | B2: Ændringsydelser | T2: =R2*S2 -> 0
A3: 16.1 | B3: Timesatser for mandtimer | T3: =R3*S3 -> 0
A4: 16.1.1 | B4: Mandtimer | T4: =R4*S4 -> 0
A5: 16.1.1.1 | B5: Entrepriseleder / projektleder / ingeniør | C5: EAT | D5: 750 | E5: 0 | F5: 0 | G5: 0 | H5: 0 | I5: 0 | J5: 0 | K5: 0 | L5: 0 | M5: 0 | N5: 0 | O5: 0 | P5: 0 | Q5: 0 | R5: 750 | S5: 1 | T5: =R5*S5 -> 750
A6: 16.1.1.2 | B6: Formand /Sjakbajs | C6: EAT | D6: 750 | E6: 0 | F6: 0 | G6: 0 | H6: 0 | I6: 0 | J6: 0 | K6: 0 | L6: 0 | M6: 0 | N6: 0 | O6: 0 | P6: 0 | Q6: 0 | R6: 750 | S6: 800 | T6: =R6*S6 -> 600000
A7: 16.1.1.3 | B7: SR1 arbejdsleder | C7: EAT | D7: 750 | E7: 0 | F7: 0 | G7: 0 | H7: 0 | I7: 0 | J7: 0 | K7: 0 | L7: 0 | M7: 0 | N7: 0 | O7: 0 | P7: 0 | Q7: 0 | R7: 750 | S7: 800 | T7: =R7*S7 -> 600000
A8: 16.1.1.4 | B8: SR2 Arbejdsleder | C8: EAT | D8: 500 | E8: 0 | F8: 0 | G8: 0 | H8: 0 | I8: 0 | J8: 0 | K8: 0 | L8: 0 | M8: 0 | N8: 0 | O8: 0 | P8: 0 | Q8: 0 | R8: 500 | S8: 1 | T8: =R8*S8 -> 500
A9: 16.1.1.8 | B9: Sporsvejser | C9: EAT | D9: 750 | E9: 0 | F9: 0 | G9: 0 | H9: 0 | I9: 0 | J9: 0 | K9: 0 | L9: 0 | M9: 0 | N9: 0 | O9: 0 | P9: 0 | Q9: 0 | R9: 750 | S9: 1 | T9: =R9*S9 -> 750
A10: 16.1.1.9 | B10: Sportekniker/sporarbejder | C10: EAT | D10: 750 | E10: 0 | F10: 0 | G10: 0 | H10: 0 | I10: 0 | J10: 0 | K10: 0 | L10: 0 | M10: 0 | N10: 0 | O10: 0 | P10: 0 | Q10: 0 | R10: 750 | S10: 1 | T10: =R10*S10 -> 750
A11: 16.1.1.10 | B11: Kørestrømsmontør | C11: EAT | D11: 750 | E11: 0 | F11: 0 | G11: 0 | H11: 0 | I11: 0 | J11: 0 | K11: 0 | L11: 0 | M11: 0 | N11: 0 | O11: 0 | P11: 0 | Q11: 0 | R11: 750 | S11: 900 | T11: =R11*S11 -> 675000
A12: 16.1.1.11 | B12: Sikringsmontør SR 2 Sikring | C12: EAT | D12: 750 | E12: 0 | F12: 0 | G12: 0 | H12: 0 | I12: 0 | J12: 0 | K12: 0 | L12: 0 | M12: 0 | N12: 0 | O12: 0 | P12: 0 | Q12: 0 | R12: 750 | S12: 1250 | T12: =R12*S12 -> 937500
A13: 16.1.1.15 | B13: PPPB Maskinfører SR | C13: EAT | D13: 250 | E13: 0 | F13: 0 | G13: 0 | H13: 0 | I13: 0 | J13: 0 | K13: 0 | L13: 0 | M13: 0 | N13: 0 | O13: 0 | P13: 0 | Q13: 0 | R13: 250 | S13: 1 | T13: =R13*S13 -> 250
A14: 16.1.1.17 | B14: Elektriker | C14: EAT | D14: 250 | E14: 0 | F14: 0 | G14: 0 | H14: 0 | I14: 0 | J14: 0 | K14: 0 | L14: 0 | M14: 0 | N14: 0 | O14: 0 | P14: 0 | Q14: 0 | R14: 250 | S14: 800 | T14: =R14*S14 -> 200000
A15: 16.1.1.18 | B15: Landmåler | C15: EAT | D15: 500 | E15: 0 | F15: 0 | G15: 0 | H15: 0 | I15: 0 | J15: 0 | K15: 0 | L15: 0 | M15: 0 | N15: 0 | O15: 0 | P15: 0 | Q15: 0 | R15: 500 | S15: 1000 | T15: =R15*S15 -> 500000
A16: 16.1.1.19 | B16: Kabelvagt | C16: EAT | D16: 1000 | E16: 0 | F16: 0 | G16: 0 | H16: 0 | I16: 0 | J16: 0 | K16: 0 | L16: 0 | M16: 0 | N16: 0 | O16: 0 | P16: 0 | Q16: 0 | R16: 1000 | S16: 700 | T16: =R16*S16 -> 700000
